2025-05-26 15:21:54,233 ERROR: Exception on /user/Александр [GET] [in d:\myblog\myenv\lib\site-packages\flask\app.py:1745]
Traceback (most recent call last):
  File "d:\myblog\myenv\lib\site-packages\flask\app.py", line 2529, in wsgi_app
    response = self.full_dispatch_request()
  File "d:\myblog\myenv\lib\site-packages\flask\app.py", line 1825, in full_dispatch_request
    rv = self.handle_user_exception(e)
  File "d:\myblog\myenv\lib\site-packages\flask\app.py", line 1823, in full_dispatch_request
    rv = self.dispatch_request()
  File "d:\myblog\myenv\lib\site-packages\flask\app.py", line 1799, in dispatch_request
    return self.ensure_sync(self.view_functions[rule.endpoint])(**view_args)
  File "d:\myblog\myenv\lib\site-packages\flask_login\utils.py", line 290, in decorated_view
    return current_app.ensure_sync(func)(*args, **kwargs)
  File "D:\myblog\app\routes.py", line 121, in user
    return render_template('user.html', user=user, posts=posts.items, next_url=next_url, prev_url=prev_url, list_followers=list_followers, list_following=list_following)
  File "d:\myblog\myenv\lib\site-packages\flask\templating.py", line 146, in render_template
    template = app.jinja_env.get_or_select_template(template_name_or_list)
  File "d:\myblog\myenv\lib\site-packages\jinja2\environment.py", line 1087, in get_or_select_template
    return self.get_template(template_name_or_list, parent, globals)
  File "d:\myblog\myenv\lib\site-packages\jinja2\environment.py", line 1016, in get_template
    return self._load_template(name, globals)
  File "d:\myblog\myenv\lib\site-packages\jinja2\environment.py", line 975, in _load_template
    template = self.loader.load(self, name, self.make_globals(globals))
  File "d:\myblog\myenv\lib\site-packages\jinja2\loaders.py", line 138, in load
    code = environment.compile(source, name, filename)
  File "d:\myblog\myenv\lib\site-packages\jinja2\environment.py", line 771, in compile
    self.handle_exception(source=source_hint)
  File "d:\myblog\myenv\lib\site-packages\jinja2\environment.py", line 942, in handle_exception
    raise rewrite_traceback_stack(source=source)
  File "D:\myblog\app\templates\user.html", line 34, in template
    {% elif not current_user.is_following(user) %}      <!-- ссылка подписки доступна только пользователю, просматривающему не свой профиль -->
jinja2.exceptions.TemplateSyntaxError: Encountered unknown tag 'elif'. Jinja was looking for the following tags: 'endblock'. The innermost block that needs to be closed is 'block'.
2025-05-26 15:23:28,129 INFO: Myblog startup [in D:\myblog\app\__init__.py:68]
2025-05-26 15:23:29,601 ERROR: Exception on /user/Александр [GET] [in d:\myblog\myenv\lib\site-packages\flask\app.py:1745]
Traceback (most recent call last):
  File "d:\myblog\myenv\lib\site-packages\flask\app.py", line 2529, in wsgi_app
    response = self.full_dispatch_request()
  File "d:\myblog\myenv\lib\site-packages\flask\app.py", line 1825, in full_dispatch_request
    rv = self.handle_user_exception(e)
  File "d:\myblog\myenv\lib\site-packages\flask\app.py", line 1823, in full_dispatch_request
    rv = self.dispatch_request()
  File "d:\myblog\myenv\lib\site-packages\flask\app.py", line 1799, in dispatch_request
    return self.ensure_sync(self.view_functions[rule.endpoint])(**view_args)
  File "d:\myblog\myenv\lib\site-packages\flask_login\utils.py", line 290, in decorated_view
    return current_app.ensure_sync(func)(*args, **kwargs)
  File "D:\myblog\app\routes.py", line 121, in user
    return render_template('user.html', user=user, posts=posts.items, next_url=next_url, prev_url=prev_url, list_followers=list_followers, list_following=list_following)
  File "d:\myblog\myenv\lib\site-packages\flask\templating.py", line 147, in render_template
    return _render(app, template, context)
  File "d:\myblog\myenv\lib\site-packages\flask\templating.py", line 130, in _render
    rv = template.render(context)
  File "d:\myblog\myenv\lib\site-packages\jinja2\environment.py", line 1295, in render
    self.environment.handle_exception()
  File "d:\myblog\myenv\lib\site-packages\jinja2\environment.py", line 942, in handle_exception
    raise rewrite_traceback_stack(source=source)
  File "D:\myblog\app\templates\user.html", line 1, in top-level template code
    {% extends "base.html" %}
  File "D:\myblog\app\templates\base.html", line 58, in top-level template code
    {% block content %}{% endblock %}
  File "D:\myblog\app\templates\user.html", line 12, in block 'content'
    <p>Подписчики: {{ user.followers_count() }}, Подписки: {{ user.following_count() }}</p>
  File "d:\myblog\myenv\lib\site-packages\jinja2\utils.py", line 92, in from_obj
    if hasattr(obj, "jinja_pass_arg"):
jinja2.exceptions.UndefinedError: 'app.models.User object' has no attribute 'followers_count'
2025-05-26 15:23:30,442 ERROR: Exception on /user/Александр [GET] [in d:\myblog\myenv\lib\site-packages\flask\app.py:1745]
Traceback (most recent call last):
  File "d:\myblog\myenv\lib\site-packages\flask\app.py", line 2529, in wsgi_app
    response = self.full_dispatch_request()
  File "d:\myblog\myenv\lib\site-packages\flask\app.py", line 1825, in full_dispatch_request
    rv = self.handle_user_exception(e)
  File "d:\myblog\myenv\lib\site-packages\flask\app.py", line 1823, in full_dispatch_request
    rv = self.dispatch_request()
  File "d:\myblog\myenv\lib\site-packages\flask\app.py", line 1799, in dispatch_request
    return self.ensure_sync(self.view_functions[rule.endpoint])(**view_args)
  File "d:\myblog\myenv\lib\site-packages\flask_login\utils.py", line 290, in decorated_view
    return current_app.ensure_sync(func)(*args, **kwargs)
  File "D:\myblog\app\routes.py", line 121, in user
    return render_template('user.html', user=user, posts=posts.items, next_url=next_url, prev_url=prev_url, list_followers=list_followers, list_following=list_following)
  File "d:\myblog\myenv\lib\site-packages\flask\templating.py", line 147, in render_template
    return _render(app, template, context)
  File "d:\myblog\myenv\lib\site-packages\flask\templating.py", line 130, in _render
    rv = template.render(context)
  File "d:\myblog\myenv\lib\site-packages\jinja2\environment.py", line 1295, in render
    self.environment.handle_exception()
  File "d:\myblog\myenv\lib\site-packages\jinja2\environment.py", line 942, in handle_exception
    raise rewrite_traceback_stack(source=source)
  File "D:\myblog\app\templates\user.html", line 1, in top-level template code
    {% extends "base.html" %}
  File "D:\myblog\app\templates\base.html", line 58, in top-level template code
    {% block content %}{% endblock %}
  File "D:\myblog\app\templates\user.html", line 12, in block 'content'
    <p>Подписчики: {{ user.followers_count() }}, Подписки: {{ user.following_count() }}</p>
  File "d:\myblog\myenv\lib\site-packages\jinja2\utils.py", line 92, in from_obj
    if hasattr(obj, "jinja_pass_arg"):
jinja2.exceptions.UndefinedError: 'app.models.User object' has no attribute 'followers_count'
2025-05-26 15:23:30,704 ERROR: Exception on /user/Александр [GET] [in d:\myblog\myenv\lib\site-packages\flask\app.py:1745]
Traceback (most recent call last):
  File "d:\myblog\myenv\lib\site-packages\flask\app.py", line 2529, in wsgi_app
    response = self.full_dispatch_request()
  File "d:\myblog\myenv\lib\site-packages\flask\app.py", line 1825, in full_dispatch_request
    rv = self.handle_user_exception(e)
  File "d:\myblog\myenv\lib\site-packages\flask\app.py", line 1823, in full_dispatch_request
    rv = self.dispatch_request()
  File "d:\myblog\myenv\lib\site-packages\flask\app.py", line 1799, in dispatch_request
    return self.ensure_sync(self.view_functions[rule.endpoint])(**view_args)
  File "d:\myblog\myenv\lib\site-packages\flask_login\utils.py", line 290, in decorated_view
    return current_app.ensure_sync(func)(*args, **kwargs)
  File "D:\myblog\app\routes.py", line 121, in user
    return render_template('user.html', user=user, posts=posts.items, next_url=next_url, prev_url=prev_url, list_followers=list_followers, list_following=list_following)
  File "d:\myblog\myenv\lib\site-packages\flask\templating.py", line 147, in render_template
    return _render(app, template, context)
  File "d:\myblog\myenv\lib\site-packages\flask\templating.py", line 130, in _render
    rv = template.render(context)
  File "d:\myblog\myenv\lib\site-packages\jinja2\environment.py", line 1295, in render
    self.environment.handle_exception()
  File "d:\myblog\myenv\lib\site-packages\jinja2\environment.py", line 942, in handle_exception
    raise rewrite_traceback_stack(source=source)
  File "D:\myblog\app\templates\user.html", line 1, in top-level template code
    {% extends "base.html" %}
  File "D:\myblog\app\templates\base.html", line 58, in top-level template code
    {% block content %}{% endblock %}
  File "D:\myblog\app\templates\user.html", line 12, in block 'content'
    <p>Подписчики: {{ user.followers_count() }}, Подписки: {{ user.following_count() }}</p>
  File "d:\myblog\myenv\lib\site-packages\jinja2\utils.py", line 92, in from_obj
    if hasattr(obj, "jinja_pass_arg"):
jinja2.exceptions.UndefinedError: 'app.models.User object' has no attribute 'followers_count'
